<sdf version='1.6'>
  <world name='default'>
    <physics name='default_physics' default='0' type='ode'>
      <ode>
        <solver>
          <type>quick</type>
          <iters>20</iters>
          <sor>1</sor>
          <use_dynamic_moi_rescaling>0</use_dynamic_moi_rescaling>
        </solver>
        <constraints>
          <cfm>0</cfm>
          <erp>0.2</erp>
          <contact_max_correcting_vel>100</contact_max_correcting_vel>
          <contact_surface_layer>0</contact_surface_layer>
        </constraints>
      </ode>
      <max_step_size>0.001</max_step_size>
      <real_time_factor>1</real_time_factor>
      <real_time_update_rate>1000</real_time_update_rate>
    </physics>
    <light name='sun' type='directional'>
      <cast_shadows>1</cast_shadows>
      <pose frame=''>0 0 10 0 -0 0</pose>
      <diffuse>0.8 0.8 0.8 1</diffuse>
      <specular>0.1 0.1 0.1 1</specular>
      <attenuation>
        <range>1000</range>
        <constant>0.9</constant>
        <linear>0.01</linear>
        <quadratic>0.001</quadratic>
      </attenuation>
      <direction>-0.5 0.5 -1</direction>
    </light>
    <model name='ground_plane'>
      <static>1</static>
      <link name='link'>
        <collision name='collision'>
          <geometry>
            <plane>
              <normal>0 0 1</normal>
              <size>100 100</size>
            </plane>
          </geometry>
          <surface>
            <friction>
              <ode>
                <mu>100</mu>
                <mu2>50</mu2>
              </ode>
              <torsional>
                <ode/>
              </torsional>
            </friction>
            <contact>
              <ode/>
            </contact>
            <bounce/>
          </surface>
          <max_contacts>10</max_contacts>
        </collision>
        <visual name='visual'>
          <cast_shadows>0</cast_shadows>
          <geometry>
            <plane>
              <normal>0 0 1</normal>
              <size>100 100</size>
            </plane>
          </geometry>
          <material>
            <script>
              <uri>file://media/materials/scripts/gazebo.material</uri>
              <name>Gazebo/Grey</name>
            </script>
          </material>
        </visual>
        <self_collide>0</self_collide>
        <kinematic>0</kinematic>
      </link>
    </model>
    <gravity>0 0 -9.8</gravity>
    <magnetic_field>6e-06 2.3e-05 -4.2e-05</magnetic_field>
    <atmosphere type='adiabatic'/>
    <scene>
      <ambient>0.4 0.4 0.4 1</ambient>
      <background>0.7 0.7 0.7 1</background>
      <shadows>1</shadows>
    </scene>
    <spherical_coordinates>
      <surface_model>EARTH_WGS84</surface_model>
      <latitude_deg>0</latitude_deg>
      <longitude_deg>0</longitude_deg>
      <elevation>0</elevation>
      <heading_deg>0</heading_deg>
    </spherical_coordinates>
    <model name='summit_xl'>
      <link name='summit_xl_base_footprint'>
        <pose frame=''>0 0 0 0 -0 0</pose>
        <inertial>
          <pose frame=''>0.009802 -0.000209 0.134689 0 -0 0</pose>
          <mass>129.68</mass>
          <inertia>
            <ixx>1.73388</ixx>
            <ixy>0.0131062</ixy>
            <ixz>-0.326245</ixz>
            <iyy>7.52688</iyy>
            <iyz>0.00399876</iyz>
            <izz>6.48435</izz>
          </inertia>
        </inertial>
        <collision name='summit_xl_base_footprint_fixed_joint_lump__summit_xl_base_link_collision'>
          <pose frame=''>0 0 0.125 0 -0 0</pose>
          <geometry>
            <mesh>
              <scale>1 1 1</scale>
              <uri>/home/ros/catkin_ws/src/summit_xl_sources/summit_xl_common/summit_xl_description/meshes/bases/hls/summit_xl_hls.dae</uri>
            </mesh>
          </geometry>
          <max_contacts>10</max_contacts>
          <surface>
            <contact>
              <ode/>
            </contact>
            <bounce/>
            <friction>
              <torsional>
                <ode/>
              </torsional>
              <ode/>
            </friction>
          </surface>
        </collision>
        <collision name='summit_xl_base_footprint_fixed_joint_lump__arm_base_link_collision_1'>
          <pose frame=''>0.255 0 0.4 0 -0 -3.14159</pose>
          <geometry>
            <mesh>
              <scale>1 1 1</scale>
              <uri>/opt/ros/kinetic/share/ur_description/meshes/ur5/collision/base.stl</uri>
            </mesh>
          </geometry>
          <max_contacts>10</max_contacts>
          <surface>
            <contact>
              <ode/>
            </contact>
            <bounce/>
            <friction>
              <torsional>
                <ode/>
              </torsional>
              <ode/>
            </friction>
          </surface>
        </collision>
        <collision name='summit_xl_base_footprint_fixed_joint_lump__summit_xl_front_laser_base_link_collision_2'>
          <pose frame=''>0.346 -0.23 0.3016 0 -0 1.5708</pose>
          <geometry>
            <cylinder>
              <length>0.0315</length>
              <radius>0.04</radius>
            </cylinder>
          </geometry>
          <max_contacts>10</max_contacts>
          <surface>
            <contact>
              <ode/>
            </contact>
            <bounce/>
            <friction>
              <torsional>
                <ode/>
              </torsional>
              <ode/>
            </friction>
          </surface>
        </collision>
        <collision name='summit_xl_base_footprint_fixed_joint_lump__summit_xl_front_rgbd_camera_link_collision_3'>
          <pose frame=''>0.375 -0.0005 0.37 0 -0 0</pose>
          <geometry>
            <mesh>
              <scale>1 1 1</scale>
              <uri>/home/ros/catkin_ws/src/summit_xl_sources/robotnik_sensors/meshes/orbbec_astra.dae</uri>
            </mesh>
          </geometry>
          <max_contacts>10</max_contacts>
          <surface>
            <contact>
              <ode/>
            </contact>
            <bounce/>
            <friction>
              <torsional>
                <ode/>
              </torsional>
              <ode/>
            </friction>
          </surface>
        </collision>
        <collision name='summit_xl_base_footprint_fixed_joint_lump__summit_xl_imu_link_collision_4'>
          <pose frame=''>-0.18 0 0.295 0 -0 0</pose>
          <geometry>
            <box>
              <size>0.001 0.001 0.001</size>
            </box>
          </geometry>
          <max_contacts>10</max_contacts>
          <surface>
            <contact>
              <ode/>
            </contact>
            <bounce/>
            <friction>
              <torsional>
                <ode/>
              </torsional>
              <ode/>
            </friction>
          </surface>
        </collision>
        <collision name='summit_xl_base_footprint_fixed_joint_lump__summit_xl_rear_laser_base_link_collision_5'>
          <pose frame=''>-0.34 0.235 0.3016 0 -0 2.35619</pose>
          <geometry>
            <cylinder>
              <length>0.06</length>
              <radius>0.035</radius>
            </cylinder>
          </geometry>
          <max_contacts>10</max_contacts>
          <surface>
            <contact>
              <ode/>
            </contact>
            <bounce/>
            <friction>
              <torsional>
                <ode/>
              </torsional>
              <ode/>
            </friction>
          </surface>
        </collision>
        <visual name='summit_xl_base_footprint_visual'>
          <pose frame=''>0 0 0 0 -0 0</pose>
          <geometry>
            <box>
              <size>0.001 0.001 0.001</size>
            </box>
          </geometry>
        </visual>
        <visual name='summit_xl_base_footprint_fixed_joint_lump__summit_xl_base_link_visual_1'>
          <pose frame=''>0 0 0.125 0 -0 0</pose>
          <geometry>
            <mesh>
              <scale>1 1 1</scale>
              <uri>/home/ros/catkin_ws/src/summit_xl_sources/summit_xl_common/summit_xl_description/meshes/bases/hls/summit_xl_hls.stl</uri>
            </mesh>
          </geometry>
        </visual>
        <visual name='summit_xl_base_footprint_fixed_joint_lump__arm_base_link_visual_2'>
          <pose frame=''>0.255 0 0.4 0 -0 -3.14159</pose>
          <geometry>
            <mesh>
              <scale>1 1 1</scale>
              <uri>/opt/ros/kinetic/share/ur_description/meshes/ur5/visual/base.dae</uri>
            </mesh>
          </geometry>
        </visual>
        <visual name='summit_xl_base_footprint_fixed_joint_lump__summit_xl_front_laser_base_link_visual_3'>
          <pose frame=''>0.346 -0.235 0.3016 0 -0 1.5708</pose>
          <geometry>
            <mesh>
              <scale>0.001 0.001 0.001</scale>
              <uri>/home/ros/catkin_ws/src/icclab_summit_xl/meshes/sensors/lds.stl</uri>
            </mesh>
          </geometry>
        </visual>
        <visual name='summit_xl_base_footprint_fixed_joint_lump__summit_xl_front_rgbd_camera_link_visual_4'>
          <pose frame=''>0.375 -0.0005 0.37 0 -0 0</pose>
          <geometry>
            <mesh>
              <scale>1 1 1</scale>
              <uri>/home/ros/catkin_ws/src/summit_xl_sources/robotnik_sensors/meshes/orbbec_astra.dae</uri>
            </mesh>
          </geometry>
        </visual>
        <visual name='summit_xl_base_footprint_fixed_joint_lump__summit_xl_imu_link_visual_5'>
          <pose frame=''>-0.18 0 0.295 0 -0 0</pose>
          <geometry>
            <box>
              <size>0.001 0.001 0.001</size>
            </box>
          </geometry>
        </visual>
        <visual name='summit_xl_base_footprint_fixed_joint_lump__summit_xl_rear_laser_base_link_visual_6'>
          <pose frame=''>-0.34 0.235 0.2816 0 -0 2.35619</pose>
          <geometry>
            <mesh>
              <scale>1 1 1</scale>
              <uri>/home/ros/catkin_ws/src/icclab_summit_xl/meshes/sensors/sweep_lidar.stl</uri>
            </mesh>
          </geometry>
        </visual>
        <velocity_decay/>
        <sensor name='summit_xl_front_laser_sensor' type='ray'>
          <visualize>0</visualize>
          <update_rate>30</update_rate>
          <ray>
            <scan>
              <horizontal>
                <samples>360</samples>
                <resolution>1</resolution>
                <min_angle>1.5708</min_angle>
                <max_angle>6.2832</max_angle>
              </horizontal>
              <vertical>
                <samples>1</samples>
                <min_angle>0</min_angle>
                <max_angle>0</max_angle>
              </vertical>
            </scan>
            <range>
              <min>0.1</min>
              <max>6</max>
              <resolution>0.01</resolution>
            </range>
            <noise>
              <type>gaussian</type>
              <mean>0</mean>
              <stddev>0.01</stddev>
            </noise>
          </ray>
          <plugin name='summit_xl_front_laser_controller' filename='libgazebo_ros_laser.so'>
            <topicName>scan_front</topicName>
            <frameName>/summit_xl_front_laser_link</frameName>
            <robotNamespace>/summit_xl/</robotNamespace>
          </plugin>
          <pose frame=''>0.346 -0.235 0.3366 0 -0 1.5708</pose>
        </sensor>
        <velocity_decay/>
        <sensor name='summit_xl_front_rgbd_camera_depth_sensor' type='depth'>
          <always_on>1</always_on>
          <update_rate>20</update_rate>
          <camera name='__default__'>
            <horizontal_fov>1.0472</horizontal_fov>
            <image>
              <format>R8G8B8</format>
              <width>640</width>
              <height>480</height>
            </image>
            <clip>
              <near>0.05</near>
              <far>3.5</far>
            </clip>
          </camera>
          <plugin name='summit_xl_front_rgbd_camera_controller' filename='libgazebo_ros_openni_kinect.so'>
            <cameraName>front_rgbd_camera</cameraName>
            <alwaysOn>true</alwaysOn>
            <updateRate>10</updateRate>
            <imageTopicName>rgb/image_raw</imageTopicName>
            <depthImageTopicName>depth/image_raw</depthImageTopicName>
            <pointCloudTopicName>depth/points</pointCloudTopicName>
            <cameraInfoTopicName>rgb/camera_info</cameraInfoTopicName>
            <depthImageCameraInfoTopicName>depth/camera_info</depthImageCameraInfoTopicName>
            <frameName>/summit_xl_front_rgbd_camera_depth_optical_frame</frameName>
            <baseline>0.1</baseline>
            <distortion_k1>0.0</distortion_k1>
            <distortion_k2>0.0</distortion_k2>
            <distortion_k3>0.0</distortion_k3>
            <distortion_t1>0.0</distortion_t1>
            <distortion_t2>0.0</distortion_t2>
            <pointCloudCutoff>0.4</pointCloudCutoff>
            <robotNamespace>/summit_xl/</robotNamespace>
          </plugin>
          <pose frame=''>0.375 0.012 0.385 0 -0 0</pose>
        </sensor>
        <gravity>1</gravity>
        <velocity_decay/>
        <self_collide>0</self_collide>
        <sensor name='summit_xl_rear_laser_sensor' type='ray'>
          <visualize>0</visualize>
          <update_rate>30</update_rate>
          <ray>
            <scan>
              <horizontal>
                <samples>360</samples>
                <resolution>1</resolution>
                <min_angle>-2.35</min_angle>
                <max_angle>2.35</max_angle>
              </horizontal>
              <vertical>
                <samples>1</samples>
                <min_angle>0</min_angle>
                <max_angle>0</max_angle>
              </vertical>
            </scan>
            <range>
              <min>0.1</min>
              <max>6</max>
              <resolution>0.01</resolution>
            </range>
            <noise>
              <type>gaussian</type>
              <mean>0</mean>
              <stddev>0.01</stddev>
            </noise>
          </ray>
          <plugin name='summit_xl_rear_laser_controller' filename='libgazebo_ros_laser.so'>
            <topicName>scan_rear</topicName>
            <frameName>/summit_xl_rear_laser_link</frameName>
            <robotNamespace>/summit_xl/</robotNamespace>
          </plugin>
          <pose frame=''>-0.34 0.235 0.3366 0 -0 2.35619</pose>
        </sensor>
        <kinematic>0</kinematic>
      </link>
      <link name='arm_shoulder_link'>
        <pose frame=''>0.255 0 0.489159 0 -0 -3.14159</pose>
        <inertial>
          <pose frame=''>0 0 0 0 -0 0</pose>
          <mass>3.7</mass>
          <inertia>
            <ixx>0.0102675</ixx>
            <ixy>0</ixy>
            <ixz>0</ixz>
            <iyy>0.0102675</iyy>
            <iyz>0</iyz>
            <izz>0.00666</izz>
          </inertia>
        </inertial>
        <collision name='arm_shoulder_link_collision'>
          <pose frame=''>0 0 0 0 -0 0</pose>
          <geometry>
            <mesh>
              <scale>1 1 1</scale>
              <uri>/opt/ros/kinetic/share/ur_description/meshes/ur5/collision/shoulder.stl</uri>
            </mesh>
          </geometry>
          <surface>
            <contact>
              <ode/>
            </contact>
            <friction>
              <ode/>
              <torsional>
                <ode/>
              </torsional>
            </friction>
            <bounce/>
          </surface>
          <max_contacts>10</max_contacts>
        </collision>
        <visual name='arm_shoulder_link_visual'>
          <pose frame=''>0 0 0 0 -0 0</pose>
          <geometry>
            <mesh>
              <scale>1 1 1</scale>
              <uri>/opt/ros/kinetic/share/ur_description/meshes/ur5/visual/shoulder.dae</uri>
            </mesh>
          </geometry>
          <material>
            <script>
              <uri>__default__</uri>
              <name>__default__</name>
            </script>
          </material>
        </visual>
        <gravity>1</gravity>
        <velocity_decay/>
        <self_collide>1</self_collide>
        <kinematic>0</kinematic>
      </link>
      <joint name='arm_shoulder_pan_joint' type='revolute'>
        <child>arm_shoulder_link</child>
        <parent>summit_xl_base_footprint</parent>
        <axis>
          <xyz>0 0 1</xyz>
          <limit>
            <lower>-3.14159</lower>
            <upper>3.14159</upper>
            <effort>150</effort>
            <velocity>3.15</velocity>
          </limit>
          <dynamics>
            <damping>0</damping>
            <friction>0</friction>
            <spring_reference>0</spring_reference>
            <spring_stiffness>0</spring_stiffness>
          </dynamics>
          <use_parent_model_frame>1</use_parent_model_frame>
        </axis>
      </joint>
      <link name='arm_upper_arm_link'>
        <pose frame=''>0.255 -0.13585 0.489159 3.14159 1.57079 3e-06</pose>
        <inertial>
          <pose frame=''>0 0 0.28 0 -0 0</pose>
          <mass>8.393</mass>
          <inertia>
            <ixx>0.226891</ixx>
            <ixy>0</ixy>
            <ixz>0</ixz>
            <iyy>0.226891</iyy>
            <iyz>0</iyz>
            <izz>0.0151074</izz>
          </inertia>
        </inertial>
        <collision name='arm_upper_arm_link_collision'>
          <pose frame=''>0 0 0 0 -0 0</pose>
          <geometry>
            <mesh>
              <scale>1 1 1</scale>
              <uri>/opt/ros/kinetic/share/ur_description/meshes/ur5/collision/upperarm.stl</uri>
            </mesh>
          </geometry>
          <surface>
            <contact>
              <ode/>
            </contact>
            <friction>
              <ode/>
              <torsional>
                <ode/>
              </torsional>
            </friction>
            <bounce/>
          </surface>
          <max_contacts>10</max_contacts>
        </collision>
        <visual name='arm_upper_arm_link_visual'>
          <pose frame=''>0 0 0 0 -0 0</pose>
          <geometry>
            <mesh>
              <scale>1 1 1</scale>
              <uri>/opt/ros/kinetic/share/ur_description/meshes/ur5/visual/upperarm.dae</uri>
            </mesh>
          </geometry>
          <material>
            <script>
              <uri>__default__</uri>
              <name>__default__</name>
            </script>
          </material>
        </visual>
        <gravity>1</gravity>
        <velocity_decay/>
        <self_collide>1</self_collide>
        <kinematic>0</kinematic>
      </link>
      <joint name='arm_shoulder_lift_joint' type='revolute'>
        <child>arm_upper_arm_link</child>
        <parent>arm_shoulder_link</parent>
        <axis>
          <xyz>0 -1 0</xyz>
          <limit>
            <lower>-3.14159</lower>
            <upper>3.14159</upper>
            <effort>150</effort>
            <velocity>3.15</velocity>
          </limit>
          <dynamics>
            <damping>0</damping>
            <friction>0</friction>
            <spring_reference>0</spring_reference>
            <spring_stiffness>0</spring_stiffness>
          </dynamics>
          <use_parent_model_frame>1</use_parent_model_frame>
        </axis>
      </joint>
      <link name='arm_forearm_link'>
        <pose frame=''>-0.17 -0.01615 0.489159 3.14159 1.57079 3e-06</pose>
        <inertial>
          <pose frame=''>0 0 0.196125 0 -0 0</pose>
          <mass>2.275</mass>
          <inertia>
            <ixx>0.0312168</ixx>
            <ixy>0</ixy>
            <ixz>0</ixz>
            <iyy>0.0312168</iyy>
            <iyz>0</iyz>
            <izz>0.004095</izz>
          </inertia>
        </inertial>
        <collision name='arm_forearm_link_collision'>
          <pose frame=''>0 0 0 0 -0 0</pose>
          <geometry>
            <mesh>
              <scale>1 1 1</scale>
              <uri>/opt/ros/kinetic/share/ur_description/meshes/ur5/collision/forearm.stl</uri>
            </mesh>
          </geometry>
          <surface>
            <contact>
              <ode/>
            </contact>
            <friction>
              <ode/>
              <torsional>
                <ode/>
              </torsional>
            </friction>
            <bounce/>
          </surface>
          <max_contacts>10</max_contacts>
        </collision>
        <visual name='arm_forearm_link_visual'>
          <pose frame=''>0 0 0 0 -0 0</pose>
          <geometry>
            <mesh>
              <scale>1 1 1</scale>
              <uri>/opt/ros/kinetic/share/ur_description/meshes/ur5/visual/forearm.dae</uri>
            </mesh>
          </geometry>
          <material>
            <script>
              <uri>__default__</uri>
              <name>__default__</name>
            </script>
          </material>
        </visual>
        <gravity>1</gravity>
        <velocity_decay/>
        <self_collide>1</self_collide>
        <kinematic>0</kinematic>
      </link>
      <joint name='arm_elbow_joint' type='revolute'>
        <child>arm_forearm_link</child>
        <parent>arm_upper_arm_link</parent>
        <axis>
          <xyz>0 -1 0</xyz>
          <limit>
            <lower>-3.14159</lower>
            <upper>3.14159</upper>
            <effort>150</effort>
            <velocity>3.15</velocity>
          </limit>
          <dynamics>
            <damping>0</damping>
            <friction>0</friction>
            <spring_reference>0</spring_reference>
            <spring_stiffness>0</spring_stiffness>
          </dynamics>
          <use_parent_model_frame>1</use_parent_model_frame>
        </axis>
      </joint>
      <link name='arm_wrist_1_link'>
        <pose frame=''>-0.56225 -0.01615 0.489159 3.14159 -0 0</pose>
        <inertial>
          <pose frame=''>0 0.093 0 0 -0 0</pose>
          <mass>1.219</mass>
          <inertia>
            <ixx>0.0025599</ixx>
            <ixy>0</ixy>
            <ixz>0</ixz>
            <iyy>0.0025599</iyy>
            <iyz>0</iyz>
            <izz>0.0021942</izz>
          </inertia>
        </inertial>
        <collision name='arm_wrist_1_link_collision'>
          <pose frame=''>0 0 0 0 -0 0</pose>
          <geometry>
            <mesh>
              <scale>1 1 1</scale>
              <uri>/opt/ros/kinetic/share/ur_description/meshes/ur5/collision/wrist1.stl</uri>
            </mesh>
          </geometry>
          <surface>
            <contact>
              <ode/>
            </contact>
            <friction>
              <ode/>
              <torsional>
                <ode/>
              </torsional>
            </friction>
            <bounce/>
          </surface>
          <max_contacts>10</max_contacts>
        </collision>
        <visual name='arm_wrist_1_link_visual'>
          <pose frame=''>0 0 0 0 -0 0</pose>
          <geometry>
            <mesh>
              <scale>1 1 1</scale>
              <uri>/opt/ros/kinetic/share/ur_description/meshes/ur5/visual/wrist1.dae</uri>
            </mesh>
          </geometry>
          <material>
            <script>
              <uri>__default__</uri>
              <name>__default__</name>
            </script>
          </material>
        </visual>
        <gravity>1</gravity>
        <velocity_decay/>
        <self_collide>1</self_collide>
        <kinematic>0</kinematic>
      </link>
      <joint name='arm_wrist_1_joint' type='revolute'>
        <child>arm_wrist_1_link</child>
        <parent>arm_forearm_link</parent>
        <axis>
          <xyz>0 -1 0</xyz>
          <limit>
            <lower>-3.14159</lower>
            <upper>3.14159</upper>
            <effort>28</effort>
            <velocity>3.2</velocity>
          </limit>
          <dynamics>
            <damping>0</damping>
            <friction>0</friction>
            <spring_reference>0</spring_reference>
            <spring_stiffness>0</spring_stiffness>
          </dynamics>
          <use_parent_model_frame>1</use_parent_model_frame>
        </axis>
      </joint>
      <link name='arm_wrist_2_link'>
        <pose frame=''>-0.56225 -0.10915 0.489159 3.14159 -0 0</pose>
        <inertial>
          <pose frame=''>-0.01977 0.022459 0.089225 0 -0 0</pose>
          <mass>1.783</mass>
          <inertia>
            <ixx>0.00849735</ixx>
            <ixy>0.00171108</ixy>
            <ixz>-0.00041331</ixz>
            <iyy>0.00806178</iyy>
            <iyz>0.00046952</iyz>
            <izz>0.00614416</izz>
          </inertia>
        </inertial>
        <collision name='arm_wrist_2_link_collision'>
          <pose frame=''>0 0 0 0 -0 0</pose>
          <geometry>
            <mesh>
              <scale>1 1 1</scale>
              <uri>/opt/ros/kinetic/share/ur_description/meshes/ur5/collision/wrist2.stl</uri>
            </mesh>
          </geometry>
          <surface>
            <contact>
              <ode/>
            </contact>
            <friction>
              <ode/>
              <torsional>
                <ode/>
              </torsional>
            </friction>
            <bounce/>
          </surface>
          <max_contacts>10</max_contacts>
        </collision>
        <collision name='arm_wrist_2_link_fixed_joint_lump__arm_camera_link_collision_1'>
          <pose frame=''>-0.0625 0.071 0.095 -1.5708 0 1.5708</pose>
          <geometry>
            <box>
              <size>0.02505 0.09 0.025</size>
            </box>
          </geometry>
          <surface>
            <contact>
              <ode/>
            </contact>
            <friction>
              <ode/>
              <torsional>
                <ode/>
              </torsional>
            </friction>
            <bounce/>
          </surface>
          <max_contacts>10</max_contacts>
        </collision>
        <collision name='arm_wrist_2_link_fixed_joint_lump__arm_collision_box_camera_cable_link_collision_2'>
          <pose frame=''>-0.0625 0.051 0.1575 -1.5708 0 1.5708</pose>
          <geometry>
            <box>
              <size>0.01 0.06 0.02</size>
            </box>
          </geometry>
          <max_contacts>10</max_contacts>
          <surface>
            <contact>
              <ode/>
            </contact>
            <bounce/>
            <friction>
              <torsional>
                <ode/>
              </torsional>
              <ode/>
            </friction>
          </surface>
        </collision>
        <collision name='arm_wrist_2_link_fixed_joint_lump__arm_camera_mount_link_collision_3'>
          <pose frame=''>0.005 0.049 0.095 3.14159 1.57079 -1.57079</pose>
          <geometry>
            <cylinder>
              <length>0.015</length>
              <radius>0.053</radius>
            </cylinder>
          </geometry>
          <max_contacts>10</max_contacts>
          <surface>
            <contact>
              <ode/>
            </contact>
            <bounce/>
            <friction>
              <torsional>
                <ode/>
              </torsional>
              <ode/>
            </friction>
          </surface>
        </collision>
        <collision name='arm_wrist_2_link_fixed_joint_lump__arm_collision_box_wrist2_link_collision_4'>
          <pose frame=''>0 0 -0.06 1.5708 -0 0</pose>
          <geometry>
            <box>
              <size>0.08 0.02 0.08</size>
            </box>
          </geometry>
          <max_contacts>10</max_contacts>
          <surface>
            <contact>
              <ode/>
            </contact>
            <bounce/>
            <friction>
              <torsional>
                <ode/>
              </torsional>
              <ode/>
            </friction>
          </surface>
        </collision>
        <visual name='arm_wrist_2_link_visual'>
          <pose frame=''>0 0 0 0 -0 0</pose>
          <geometry>
            <mesh>
              <scale>1 1 1</scale>
              <uri>/opt/ros/kinetic/share/ur_description/meshes/ur5/visual/wrist2.dae</uri>
            </mesh>
          </geometry>
          <material>
            <script>
              <uri>__default__</uri>
              <name>__default__</name>
            </script>
          </material>
        </visual>
        <visual name='arm_wrist_2_link_fixed_joint_lump__arm_camera_link_visual_1'>
          <pose frame=''>-0.0625 0.071 0.0924 -1.5708 0 1.5708</pose>
          <geometry>
            <mesh>
              <scale>1 1 1</scale>
              <uri>/home/ros/catkin_ws/src/summit_xl_sources/robotnik_sensors/meshes/intel_realsense_depth_camera_d435.dae</uri>
            </mesh>
          </geometry>
          <material>
            <script>
              <uri>__default__</uri>
              <name>__default__</name>
            </script>
          </material>
        </visual>
        <visual name='arm_wrist_2_link_fixed_joint_lump__arm_camera_mount_link_visual_2'>
          <pose frame=''>0 0.041 0.09 3.14159 1.57079 -1.57079</pose>
          <geometry>
            <mesh>
              <scale>0.00095 0.00095 0.00095</scale>
              <uri>/home/ros/catkin_ws/src/icclab_summit_xl/meshes/camera_mount/RealSense_D435_UR5_camera_mount.stl</uri>
            </mesh>
          </geometry>
        </visual>
        <velocity_decay/>
        <gravity>1</gravity>
        <velocity_decay/>
        <self_collide>0</self_collide>
        <sensor name='arm_depth_sensor' type='depth'>
          <always_on>1</always_on>
          <update_rate>5</update_rate>
          <camera name='__default__'>
            <horizontal_fov>1.59174</horizontal_fov>
            <image>
              <format>R8G8B8</format>
              <width>640</width>
              <height>480</height>
            </image>
            <clip>
              <near>0.3</near>
              <far>10</far>
            </clip>
          </camera>
          <plugin name='arm_controller' filename='libgazebo_ros_openni_kinect.so'>
            <cameraName>arm_camera</cameraName>
            <alwaysOn>true</alwaysOn>
            <updateRate>5</updateRate>
            <imageTopicName>rgb/image_raw</imageTopicName>
            <depthImageTopicName>depth/image_raw</depthImageTopicName>
            <pointCloudTopicName>depth_registered/points</pointCloudTopicName>
            <cameraInfoTopicName>rgb/camera_info</cameraInfoTopicName>
            <depthImageCameraInfoTopicName>depth/camera_info</depthImageCameraInfoTopicName>
            <frameName>/arm_camera_depth_optical_frame</frameName>
            <baseline>0.1</baseline>
            <distortion_k1>0.0</distortion_k1>
            <distortion_k2>0.0</distortion_k2>
            <distortion_k3>0.0</distortion_k3>
            <distortion_t1>0.0</distortion_t1>
            <distortion_t2>0.0</distortion_t2>
            <pointCloudCutoff>0.4</pointCloudCutoff>
            <robotNamespace>/summit_xl/</robotNamespace>
          </plugin>
          <pose frame=''>-0.0625 0.071 0.0775 -1.5708 0 1.5708</pose>
        </sensor>
        <kinematic>0</kinematic>
      </link>
      <joint name='arm_wrist_2_joint' type='revolute'>
        <child>arm_wrist_2_link</child>
        <parent>arm_wrist_1_link</parent>
        <axis>
          <xyz>0 0 -1</xyz>
          <limit>
            <lower>-3.14159</lower>
            <upper>3.14159</upper>
            <effort>28</effort>
            <velocity>3.2</velocity>
          </limit>
          <dynamics>
            <damping>0</damping>
            <friction>0</friction>
            <spring_reference>0</spring_reference>
            <spring_stiffness>0</spring_stiffness>
          </dynamics>
          <use_parent_model_frame>1</use_parent_model_frame>
        </axis>
      </joint>
      <link name='arm_wrist_3_link'>
        <pose frame=''>-0.56225 -0.10915 0.394509 3.14159 -0 0</pose>
        <inertial>
          <pose frame=''>0 0.074898 0 1.5708 -0 0</pose>
          <mass>0.4379</mass>
          <inertia>
            <ixx>0.000283283</ixx>
            <ixy>0</ixy>
            <ixz>0</ixz>
            <iyy>0.000283283</iyy>
            <iyz>-6.59796e-16</iyz>
            <izz>0.000382117</izz>
          </inertia>
        </inertial>
        <collision name='arm_wrist_3_link_collision'>
          <pose frame=''>0 0 0 0 -0 0</pose>
          <geometry>
            <mesh>
              <scale>1 1 1</scale>
              <uri>/opt/ros/kinetic/share/ur_description/meshes/ur5/collision/wrist3.stl</uri>
            </mesh>
          </geometry>
          <surface>
            <contact>
              <ode/>
            </contact>
            <friction>
              <ode/>
              <torsional>
                <ode/>
              </torsional>
            </friction>
            <bounce/>
          </surface>
          <max_contacts>10</max_contacts>
        </collision>
        <collision name='arm_wrist_3_link_fixed_joint_lump__arm_collision_box_wrist3_link_collision_1'>
          <pose frame=''>0 -0.06 0 0 -0 0</pose>
          <geometry>
            <box>
              <size>0.08 0.02 0.08</size>
            </box>
          </geometry>
          <max_contacts>10</max_contacts>
          <surface>
            <contact>
              <ode/>
            </contact>
            <bounce/>
            <friction>
              <torsional>
                <ode/>
              </torsional>
              <ode/>
            </friction>
          </surface>
        </collision>
        <collision name='arm_wrist_3_link_fixed_joint_lump__arm_ee_link_collision_2'>
          <pose frame=''>-0 0.0723 0 0 -0 1.5708</pose>
          <geometry>
            <box>
              <size>0.01 0.01 0.01</size>
            </box>
          </geometry>
          <surface>
            <contact>
              <ode/>
            </contact>
            <friction>
              <ode/>
              <torsional>
                <ode/>
              </torsional>
            </friction>
            <bounce/>
          </surface>
          <max_contacts>10</max_contacts>
        </collision>
        <collision name='arm_wrist_3_link_fixed_joint_lump__gripper_base_link_collision_3'>
          <pose frame=''>0 0.0823 0 -1.5708 0 0</pose>
          <geometry>
            <mesh>
              <scale>1 1 1</scale>
              <uri>/home/ros/catkin_ws/src/icclab_summit_xl/meshes/gripper/schunk_epg40/schunk_epg40_base.stl</uri>
            </mesh>
          </geometry>
          <surface>
            <contact>
              <ode/>
            </contact>
            <friction>
              <ode/>
              <torsional>
                <ode/>
              </torsional>
            </friction>
            <bounce/>
          </surface>
          <max_contacts>10</max_contacts>
        </collision>
        <visual name='arm_wrist_3_link_visual'>
          <pose frame=''>0 0 0 0 -0 0</pose>
          <geometry>
            <mesh>
              <scale>1 1 1</scale>
              <uri>/opt/ros/kinetic/share/ur_description/meshes/ur5/visual/wrist3.dae</uri>
            </mesh>
          </geometry>
          <material>
            <script>
              <uri>__default__</uri>
              <name>__default__</name>
            </script>
          </material>
        </visual>
        <visual name='arm_wrist_3_link_fixed_joint_lump__gripper_base_link_visual_1'>
          <pose frame=''>0 0.0823 0 -1.5708 0 0</pose>
          <geometry>
            <mesh>
              <scale>1 1 1</scale>
              <uri>/home/ros/catkin_ws/src/icclab_summit_xl/meshes/gripper/schunk_epg40/schunk_epg40_base.stl</uri>
            </mesh>
          </geometry>
          <material>
            <script>
              <name>Gazebo/Grey</name>
              <uri>file://media/materials/scripts/gazebo.material</uri>
            </script>
          </material>
        </visual>
        <velocity_decay/>
        <velocity_decay/>
        <gravity>1</gravity>
        <velocity_decay/>
        <self_collide>0</self_collide>
        <kinematic>0</kinematic>
      </link>
      <joint name='arm_wrist_3_joint' type='revolute'>
        <child>arm_wrist_3_link</child>
        <parent>arm_wrist_2_link</parent>
        <axis>
          <xyz>0 -1 0</xyz>
          <limit>
            <lower>-3.14159</lower>
            <upper>3.14159</upper>
            <effort>28</effort>
            <velocity>3.2</velocity>
          </limit>
          <dynamics>
            <damping>0</damping>
            <friction>0</friction>
            <spring_reference>0</spring_reference>
            <spring_stiffness>0</spring_stiffness>
          </dynamics>
          <use_parent_model_frame>1</use_parent_model_frame>
        </axis>
      </joint>
      <link name='gripper_left_finger_base_link'>
        <pose frame=''>-0.57425 -0.2806 0.394509 1.5708 -0 0</pose>
        <inertial>
          <pose frame=''>0.006 0 0.025 0 -0 0</pose>
          <mass>0.04</mass>
          <inertia>
            <ixx>2.63333e-05</ixx>
            <ixy>0</ixy>
            <ixz>-6e-06</ixz>
            <iyy>2.77733e-05</iyy>
            <iyz>0</iyz>
            <izz>3.44e-06</izz>
          </inertia>
        </inertial>
        <collision name='gripper_left_finger_base_link_collision'>
          <pose frame=''>0 0 0 0 -0 0</pose>
          <geometry>
            <mesh>
              <scale>1 1 1</scale>
              <uri>/home/ros/catkin_ws/src/icclab_summit_xl/meshes/gripper/schunk_epg40/schunk_epg40_finger_base.stl</uri>
            </mesh>
          </geometry>
          <max_contacts>10</max_contacts>
          <surface>
            <contact>
              <ode/>
            </contact>
            <bounce/>
            <friction>
              <torsional>
                <ode/>
              </torsional>
              <ode/>
            </friction>
          </surface>
        </collision>
        <collision name='gripper_left_finger_base_link_fixed_joint_lump__gripper_left_finger_link_collision_1'>
          <pose frame=''>0.012 0 0.05 0 -0 0</pose>
          <geometry>
            <mesh>
              <scale>1 1 1</scale>
              <uri>/home/ros/catkin_ws/src/icclab_summit_xl/meshes/gripper/schunk_epg40/schunk_epg40_finger.stl</uri>
            </mesh>
          </geometry>
          <surface>
            <contact>
              <ode>
                <kp>1e+06</kp>
                <kd>1</kd>
                <min_depth>0.001</min_depth>
              </ode>
            </contact>
            <friction>
              <ode>
                <mu>1</mu>
                <mu2>1</mu2>
              </ode>
              <torsional>
                <ode/>
              </torsional>
            </friction>
            <bounce/>
          </surface>
          <max_contacts>10</max_contacts>
        </collision>
        <visual name='gripper_left_finger_base_link_visual'>
          <pose frame=''>0 0 0 0 -0 0</pose>
          <geometry>
            <mesh>
              <scale>1 1 1</scale>
              <uri>/home/ros/catkin_ws/src/icclab_summit_xl/meshes/gripper/schunk_epg40/schunk_epg40_finger_base.stl</uri>
            </mesh>
          </geometry>
        </visual>
        <visual name='gripper_left_finger_base_link_fixed_joint_lump__gripper_left_finger_link_visual_1'>
          <pose frame=''>0.012 0 0.05 0 -0 0</pose>
          <geometry>
            <mesh>
              <scale>1 1 1</scale>
              <uri>/home/ros/catkin_ws/src/icclab_summit_xl/meshes/gripper/schunk_epg40/schunk_epg40_finger.stl</uri>
            </mesh>
          </geometry>
          <material>
            <script>
              <uri>__default__</uri>
              <name>__default__</name>
            </script>
          </material>
        </visual>
        <gravity>1</gravity>
        <velocity_decay/>
        <self_collide>0</self_collide>
        <kinematic>0</kinematic>
      </link>
      <joint name='gripper_left_finger_base_joint' type='prismatic'>
        <child>gripper_left_finger_base_link</child>
        <parent>arm_wrist_3_link</parent>
        <axis>
          <xyz>-1 -0 0</xyz>
          <limit>
            <lower>0.001</lower>
            <upper>0.035</upper>
            <effort>10</effort>
            <velocity>0.041</velocity>
          </limit>
          <dynamics>
            <spring_reference>0</spring_reference>
            <spring_stiffness>0</spring_stiffness>
          </dynamics>
          <use_parent_model_frame>1</use_parent_model_frame>
        </axis>
        <physics>
          <ode>
            <limit>
              <cfm>0</cfm>
              <erp>0.2</erp>
            </limit>
            <implicit_spring_damper>1</implicit_spring_damper>
            <cfm_damping>1</cfm_damping>
          </ode>
        </physics>
      </joint>
      <link name='gripper_right_finger_base_link'>
        <pose frame=''>-0.55025 -0.2806 0.394509 -1.5708 -0.001593 -3.14159</pose>
        <inertial>
          <pose frame=''>0.006 0 0.025 0 -0 0</pose>
          <mass>0.04</mass>
          <inertia>
            <ixx>2.63333e-05</ixx>
            <ixy>0</ixy>
            <ixz>-6e-06</ixz>
            <iyy>2.77733e-05</iyy>
            <iyz>0</iyz>
            <izz>3.44e-06</izz>
          </inertia>
        </inertial>
        <collision name='gripper_right_finger_base_link_collision'>
          <pose frame=''>0 0 0 0 -0 0</pose>
          <geometry>
            <mesh>
              <scale>1 1 1</scale>
              <uri>/home/ros/catkin_ws/src/icclab_summit_xl/meshes/gripper/schunk_epg40/schunk_epg40_finger_base.stl</uri>
            </mesh>
          </geometry>
          <max_contacts>10</max_contacts>
          <surface>
            <contact>
              <ode/>
            </contact>
            <bounce/>
            <friction>
              <torsional>
                <ode/>
              </torsional>
              <ode/>
            </friction>
          </surface>
        </collision>
        <collision name='gripper_right_finger_base_link_fixed_joint_lump__gripper_right_finger_link_collision_1'>
          <pose frame=''>0.012 0 0.05 0 -0 0</pose>
          <geometry>
            <mesh>
              <scale>1 1 1</scale>
              <uri>/home/ros/catkin_ws/src/icclab_summit_xl/meshes/gripper/schunk_epg40/schunk_epg40_finger.stl</uri>
            </mesh>
          </geometry>
          <surface>
            <contact>
              <ode>
                <kp>1e+06</kp>
                <kd>1</kd>
                <min_depth>0.001</min_depth>
              </ode>
            </contact>
            <friction>
              <ode>
                <mu>1</mu>
                <mu2>1</mu2>
              </ode>
              <torsional>
                <ode/>
              </torsional>
            </friction>
            <bounce/>
          </surface>
          <max_contacts>10</max_contacts>
        </collision>
        <visual name='gripper_right_finger_base_link_visual'>
          <pose frame=''>0 0 0 0 -0 0</pose>
          <geometry>
            <mesh>
              <scale>1 1 1</scale>
              <uri>/home/ros/catkin_ws/src/icclab_summit_xl/meshes/gripper/schunk_epg40/schunk_epg40_finger_base.stl</uri>
            </mesh>
          </geometry>
        </visual>
        <visual name='gripper_right_finger_base_link_fixed_joint_lump__gripper_right_finger_link_visual_1'>
          <pose frame=''>0.012 0 0.05 0 -0 0</pose>
          <geometry>
            <mesh>
              <scale>1 1 1</scale>
              <uri>/home/ros/catkin_ws/src/icclab_summit_xl/meshes/gripper/schunk_epg40/schunk_epg40_finger.stl</uri>
            </mesh>
          </geometry>
          <material>
            <script>
              <uri>__default__</uri>
              <name>__default__</name>
            </script>
          </material>
        </visual>
        <gravity>1</gravity>
        <velocity_decay/>
        <self_collide>0</self_collide>
        <kinematic>0</kinematic>
      </link>
      <joint name='gripper_right_finger_base_joint' type='prismatic'>
        <child>gripper_right_finger_base_link</child>
        <parent>arm_wrist_3_link</parent>
        <axis>
          <xyz>0.999999 0 -0.001593</xyz>
          <limit>
            <lower>0.001</lower>
            <upper>0.035</upper>
            <effort>10</effort>
            <velocity>0.041</velocity>
          </limit>
          <dynamics>
            <spring_reference>0</spring_reference>
            <spring_stiffness>0</spring_stiffness>
          </dynamics>
          <use_parent_model_frame>1</use_parent_model_frame>
        </axis>
      </joint>
      <link name='summit_xl_back_left_wheel_link'>
        <pose frame=''>-0.2225 0.2045 0.125 0 -0 0</pose>
        <inertial>
          <pose frame=''>0 0 0 0 -0 0</pose>
          <mass>6.5</mass>
          <inertia>
            <ixx>0.0360073</ixx>
            <ixy>0</ixy>
            <ixz>0</ixz>
            <iyy>0.0360073</iyy>
            <iyz>0</iyz>
            <izz>0.0507812</izz>
          </inertia>
        </inertial>
        <collision name='summit_xl_back_left_wheel_link_collision'>
          <pose frame=''>0 0 0 1.5708 -0 0</pose>
          <geometry>
            <cylinder>
              <length>0.14</length>
              <radius>0.125</radius>
            </cylinder>
          </geometry>
          <surface>
            <contact>
              <ode>
                <kp>1e+07</kp>
                <kd>1</kd>
              </ode>
            </contact>
            <friction>
              <ode>
                <mu>1</mu>
                <mu2>1</mu2>
                <fdir1>1 0 0</fdir1>
              </ode>
              <torsional>
                <ode/>
              </torsional>
            </friction>
            <bounce/>
          </surface>
          <max_contacts>10</max_contacts>
        </collision>
        <visual name='summit_xl_back_left_wheel_link_visual'>
          <pose frame=''>0 0 0 0 -0 0</pose>
          <geometry>
            <mesh>
              <scale>1 1 1</scale>
              <uri>/home/ros/catkin_ws/src/summit_xl_sources/summit_xl_common/summit_xl_description/meshes/wheels/omni_wheel_1.dae</uri>
            </mesh>
          </geometry>
          <material>
            <script>
              <uri>__default__</uri>
              <name>__default__</name>
            </script>
          </material>
        </visual>
        <gravity>1</gravity>
        <velocity_decay/>
        <self_collide>0</self_collide>
        <kinematic>0</kinematic>
      </link>
      <joint name='summit_xl_back_left_wheel_joint' type='revolute'>
        <child>summit_xl_back_left_wheel_link</child>
        <parent>summit_xl_base_footprint</parent>
        <axis>
          <xyz>0 1 0</xyz>
          <limit>
            <lower>-1e+16</lower>
            <upper>1e+16</upper>
          </limit>
          <dynamics>
            <spring_reference>0</spring_reference>
            <spring_stiffness>0</spring_stiffness>
          </dynamics>
          <use_parent_model_frame>1</use_parent_model_frame>
        </axis>
      </joint>
      <link name='summit_xl_back_right_wheel_link'>
        <pose frame=''>-0.2225 -0.2045 0.125 0 -0 0</pose>
        <inertial>
          <pose frame=''>0 0 0 0 -0 0</pose>
          <mass>6.5</mass>
          <inertia>
            <ixx>0.0360073</ixx>
            <ixy>0</ixy>
            <ixz>0</ixz>
            <iyy>0.0360073</iyy>
            <iyz>0</iyz>
            <izz>0.0507812</izz>
          </inertia>
        </inertial>
        <collision name='summit_xl_back_right_wheel_link_collision'>
          <pose frame=''>0 0 0 1.5708 -0 0</pose>
          <geometry>
            <cylinder>
              <length>0.14</length>
              <radius>0.125</radius>
            </cylinder>
          </geometry>
          <surface>
            <contact>
              <ode>
                <kp>1e+07</kp>
                <kd>1</kd>
              </ode>
            </contact>
            <friction>
              <ode>
                <mu>1</mu>
                <mu2>1</mu2>
                <fdir1>1 0 0</fdir1>
              </ode>
              <torsional>
                <ode/>
              </torsional>
            </friction>
            <bounce/>
          </surface>
          <max_contacts>10</max_contacts>
        </collision>
        <visual name='summit_xl_back_right_wheel_link_visual'>
          <pose frame=''>0 0 0 0 -0 0</pose>
          <geometry>
            <mesh>
              <scale>1 1 1</scale>
              <uri>/home/ros/catkin_ws/src/summit_xl_sources/summit_xl_common/summit_xl_description/meshes/wheels/omni_wheel_2.dae</uri>
            </mesh>
          </geometry>
          <material>
            <script>
              <uri>__default__</uri>
              <name>__default__</name>
            </script>
          </material>
        </visual>
        <gravity>1</gravity>
        <velocity_decay/>
        <self_collide>0</self_collide>
        <kinematic>0</kinematic>
      </link>
      <joint name='summit_xl_back_right_wheel_joint' type='revolute'>
        <child>summit_xl_back_right_wheel_link</child>
        <parent>summit_xl_base_footprint</parent>
        <axis>
          <xyz>0 1 0</xyz>
          <limit>
            <lower>-1e+16</lower>
            <upper>1e+16</upper>
          </limit>
          <dynamics>
            <spring_reference>0</spring_reference>
            <spring_stiffness>0</spring_stiffness>
          </dynamics>
          <use_parent_model_frame>1</use_parent_model_frame>
        </axis>
      </joint>
      <link name='summit_xl_front_left_wheel_link'>
        <pose frame=''>0.2225 0.2045 0.125 0 -0 0</pose>
        <inertial>
          <pose frame=''>0 0 0 0 -0 0</pose>
          <mass>6.5</mass>
          <inertia>
            <ixx>0.0360073</ixx>
            <ixy>0</ixy>
            <ixz>0</ixz>
            <iyy>0.0360073</iyy>
            <iyz>0</iyz>
            <izz>0.0507812</izz>
          </inertia>
        </inertial>
        <collision name='summit_xl_front_left_wheel_link_collision'>
          <pose frame=''>0 0 0 1.5708 -0 0</pose>
          <geometry>
            <cylinder>
              <length>0.14</length>
              <radius>0.125</radius>
            </cylinder>
          </geometry>
          <surface>
            <contact>
              <ode>
                <kp>1e+07</kp>
                <kd>1</kd>
              </ode>
            </contact>
            <friction>
              <ode>
                <mu>1</mu>
                <mu2>1</mu2>
                <fdir1>1 0 0</fdir1>
              </ode>
              <torsional>
                <ode/>
              </torsional>
            </friction>
            <bounce/>
          </surface>
          <max_contacts>10</max_contacts>
        </collision>
        <visual name='summit_xl_front_left_wheel_link_visual'>
          <pose frame=''>0 0 0 0 -0 0</pose>
          <geometry>
            <mesh>
              <scale>1 1 1</scale>
              <uri>/home/ros/catkin_ws/src/summit_xl_sources/summit_xl_common/summit_xl_description/meshes/wheels/omni_wheel_1.dae</uri>
            </mesh>
          </geometry>
          <material>
            <script>
              <uri>__default__</uri>
              <name>__default__</name>
            </script>
          </material>
        </visual>
        <gravity>1</gravity>
        <velocity_decay/>
        <self_collide>0</self_collide>
        <kinematic>0</kinematic>
      </link>
      <joint name='summit_xl_front_left_wheel_joint' type='revolute'>
        <child>summit_xl_front_left_wheel_link</child>
        <parent>summit_xl_base_footprint</parent>
        <axis>
          <xyz>0 1 0</xyz>
          <limit>
            <lower>-1e+16</lower>
            <upper>1e+16</upper>
          </limit>
          <dynamics>
            <spring_reference>0</spring_reference>
            <spring_stiffness>0</spring_stiffness>
          </dynamics>
          <use_parent_model_frame>1</use_parent_model_frame>
        </axis>
      </joint>
      <link name='summit_xl_front_right_wheel_link'>
        <pose frame=''>0.2225 -0.2045 0.125 0 -0 0</pose>
        <inertial>
          <pose frame=''>0 0 0 0 -0 0</pose>
          <mass>6.5</mass>
          <inertia>
            <ixx>0.0360073</ixx>
            <ixy>0</ixy>
            <ixz>0</ixz>
            <iyy>0.0360073</iyy>
            <iyz>0</iyz>
            <izz>0.0507812</izz>
          </inertia>
        </inertial>
        <collision name='summit_xl_front_right_wheel_link_collision'>
          <pose frame=''>0 0 0 1.5708 -0 0</pose>
          <geometry>
            <cylinder>
              <length>0.14</length>
              <radius>0.125</radius>
            </cylinder>
          </geometry>
          <surface>
            <contact>
              <ode>
                <kp>1e+07</kp>
                <kd>1</kd>
              </ode>
            </contact>
            <friction>
              <ode>
                <mu>1</mu>
                <mu2>1</mu2>
                <fdir1>1 0 0</fdir1>
              </ode>
              <torsional>
                <ode/>
              </torsional>
            </friction>
            <bounce/>
          </surface>
          <max_contacts>10</max_contacts>
        </collision>
        <visual name='summit_xl_front_right_wheel_link_visual'>
          <pose frame=''>0 0 0 0 -0 0</pose>
          <geometry>
            <mesh>
              <scale>1 1 1</scale>
              <uri>/home/ros/catkin_ws/src/summit_xl_sources/summit_xl_common/summit_xl_description/meshes/wheels/omni_wheel_2.dae</uri>
            </mesh>
          </geometry>
          <material>
            <script>
              <uri>__default__</uri>
              <name>__default__</name>
            </script>
          </material>
        </visual>
        <gravity>1</gravity>
        <velocity_decay/>
        <self_collide>0</self_collide>
        <kinematic>0</kinematic>
      </link>
      <joint name='summit_xl_front_right_wheel_joint' type='revolute'>
        <child>summit_xl_front_right_wheel_link</child>
        <parent>summit_xl_base_footprint</parent>
        <axis>
          <xyz>0 1 0</xyz>
          <limit>
            <lower>-1e+16</lower>
            <upper>1e+16</upper>
          </limit>
          <dynamics>
            <spring_reference>0</spring_reference>
            <spring_stiffness>0</spring_stiffness>
          </dynamics>
          <use_parent_model_frame>1</use_parent_model_frame>
        </axis>
      </joint>
      <plugin name='ros_control' filename='libgazebo_ros_control.so'>
        <robotParam>robot_description</robotParam>
        <controlPeriod>0.001</controlPeriod>
        <robotSimType>gazebo_ros_control/DefaultRobotHWSim</robotSimType>
        <robotNamespace>/summit_xl/</robotNamespace>
      </plugin>
      <plugin name='omni_steering' filename='libgazebo_ros_planar_move.so'>
        <commandTopic>robotnik_base_control/cmd_vel</commandTopic>
        <odometryTopic>robotnik_base_control/odom</odometryTopic>
        <odometryFrame>summit_xl_odom</odometryFrame>
        <odometryRate>50.0</odometryRate>
        <robotBaseFrame>summit_xl_base_footprint</robotBaseFrame>
        <publishTF>false</publishTF>
        <robotNamespace>/summit_xl/</robotNamespace>
      </plugin>
      <plugin name='summit_xl_imu_controller' filename='libhector_gazebo_ros_imu.so'>
        <alwaysOn>true</alwaysOn>
        <topicName>imu/data</topicName>
        <serviceName>summit_xl_imuimu/service</serviceName>
        <frameId>summit_xl_imu_link</frameId>
        <updateRate>50.0</updateRate>
        <gaussianNoise>0.005</gaussianNoise>
        <yawOffset>0.0</yawOffset>
        <yawDrift>0.02</yawDrift>
        <yawGaussianNoise>0.01</yawGaussianNoise>
        <rateOffset>0.0 0.0 0.0</rateOffset>
        <rateDrift>0.002 0.002 0.002</rateDrift>
        <rateGaussianNoise>0.001 0.001 0.001</rateGaussianNoise>
        <accelOffset>0.0 0.0 0.0</accelOffset>
        <accelDrift>0.005 0.005 0.005</accelDrift>
        <accelGaussianNoise>0.005 0.005 0.005</accelGaussianNoise>
        <robotNamespace>/summit_xl/</robotNamespace>
        <bodyName>summit_xl_base_footprint</bodyName>
        <xyzOffset>0.18 0 -0.295</xyzOffset>
        <rpyOffset>0 -0 0</rpyOffset>
      </plugin>
      <plugin name='ft_sensor_l' filename='libgazebo_ros_ft_sensor.so'>
        <updateRate>100.0</updateRate>
        <topicName>ft_sensor_left_finger</topicName>
        <jointName>gripper_left_finger_base_joint</jointName>
        <robotNamespace>/summit_xl/</robotNamespace>
      </plugin>
      <plugin name='ft_sensor_r' filename='libgazebo_ros_ft_sensor.so'>
        <updateRate>100.0</updateRate>
        <topicName>ft_sensor_right_finger</topicName>
        <jointName>gripper_right_finger_base_joint</jointName>
        <robotNamespace>/summit_xl/</robotNamespace>
      </plugin>
      <static>0</static>
      <plugin name='gazebo_grasp_fix' filename='libgazebo_grasp_fix.so'>
        <arm>
          <arm_name>ur5-arm</arm_name>
          <palm_link>arm_wrist_3_link</palm_link>
          <gripper_link>gripper_left_finger_base_link</gripper_link>
          <gripper_link>gripper_right_finger_base_link</gripper_link>
        </arm>
        <forces_angle_tolerance>90</forces_angle_tolerance>
        <update_rate>4</update_rate>
        <grip_count_threshold>1</grip_count_threshold>
        <max_grip_count>8</max_grip_count>
        <release_tolerance>0.001</release_tolerance>
        <disable_collisions_on_attach>false</disable_collisions_on_attach>
        <contact_topic>__default_topic__</contact_topic>
        <robotNamespace>/summit_xl/</robotNamespace>
      </plugin>
      <pose frame=''>0 0 0 0 -0 0</pose>
    </model>
    <model name='drill'>
      <link name='link'>
        <inertial>
          <pose frame=''>-0.00637 -0.008 0.13254 0 -0 0</pose>
          <inertia>
            <ixx>0.0133113</ixx>
            <ixy>-0.00030365</ixy>
            <ixz>-0.00034148</ixz>
            <iyy>0.0115766</iyy>
            <iyz>0.00088073</iyz>
            <izz>0.00378028</izz>
          </inertia>
          <mass>1.50252</mass>
        </inertial>
        <collision name='collision'>
          <pose frame=''>0 0 -0.09 0 -0 0</pose>
          <geometry>
            <mesh>
              <uri>model://cordless_drill/meshes/cordless_drill.stl</uri>
            </mesh>
          </geometry>
          <surface>
            <contact>
              <ode>
                <max_vel>0.1</max_vel>
                <min_depth>0.001</min_depth>
              </ode>
            </contact>
            <bounce/>
            <friction>
              <torsional>
                <ode/>
              </torsional>
              <ode/>
            </friction>
          </surface>
          <max_contacts>10</max_contacts>
        </collision>
        <visual name='visual'>
          <pose frame=''>0 0 -0.09 0 -0 0</pose>
          <geometry>
            <mesh>
              <uri>model://cordless_drill/meshes/cordless_drill.dae</uri>
            </mesh>
          </geometry>
        </visual>
        <self_collide>0</self_collide>
        <kinematic>0</kinematic>
      </link>
      <pose frame=''>0.745415 0.094711 0 0 -0 0</pose>
    </model>
    <model name='wooden_case'>
      <link name='base'>
        <pose frame=''>0 0 0.024 0 -0 0</pose>
        <inertial>
          <pose frame=''>-0.022184 0 0.171592 0 -0 0</pose>
          <mass>3.96264</mass>
          <inertia>
            <ixx>0.213536</ixx>
            <ixy>0</ixy>
            <ixz>0.000779377</ixz>
            <iyy>0.0708943</iyy>
            <iyz>0</iyz>
            <izz>0.154604</izz>
          </inertia>
        </inertial>
        <collision name='collision_back'>
          <pose frame=''>-0.053975 0 0.1778 0 -0 0</pose>
          <geometry>
            <box>
              <size>0.01905 0.5461 0.3175</size>
            </box>
          </geometry>
          <surface>
            <contact>
              <poissons_ratio>0.347</poissons_ratio>
              <elastic_modulus>8.8e+09</elastic_modulus>
              <ode>
                <kp>100000</kp>
                <kd>100</kd>
                <max_vel>100</max_vel>
                <min_depth>0.001</min_depth>
              </ode>
            </contact>
            <friction>
              <torsional>
                <coefficient>1</coefficient>
                <use_patch_radius>0</use_patch_radius>
                <surface_radius>0.01</surface_radius>
                <ode/>
              </torsional>
              <ode/>
            </friction>
            <bounce/>
          </surface>
          <max_contacts>10</max_contacts>
        </collision>
        <visual name='visual_back'>
          <pose frame=''>-0.053975 0 0.1778 0 -0 0</pose>
          <geometry>
            <box>
              <size>0.01905 0.5461 0.3175</size>
            </box>
          </geometry>
          <material>
            <script>
              <uri>file://media/materials/scripts/gazebo.material</uri>
              <name>Gazebo/Wood</name>
            </script>
          </material>
        </visual>
        <collision name='collision_bottom'>
          <pose frame=''>0 0 0.009525 0 -0 0</pose>
          <geometry>
            <box>
              <size>0.127 0.5842 0.01905</size>
            </box>
          </geometry>
          <surface>
            <contact>
              <poissons_ratio>0.347</poissons_ratio>
              <elastic_modulus>8.8e+09</elastic_modulus>
              <ode>
                <kp>100000</kp>
                <kd>100</kd>
                <max_vel>100</max_vel>
                <min_depth>0.001</min_depth>
              </ode>
            </contact>
            <friction>
              <torsional>
                <coefficient>1</coefficient>
                <use_patch_radius>0</use_patch_radius>
                <surface_radius>0.01</surface_radius>
                <ode/>
              </torsional>
              <ode/>
            </friction>
            <bounce/>
          </surface>
          <max_contacts>10</max_contacts>
        </collision>
        <visual name='visual_bottom'>
          <pose frame=''>0 0 0.009525 0 -0 0</pose>
          <geometry>
            <box>
              <size>0.127 0.5842 0.01905</size>
            </box>
          </geometry>
          <material>
            <script>
              <uri>file://media/materials/scripts/gazebo.material</uri>
              <name>Gazebo/Wood</name>
            </script>
          </material>
        </visual>
        <collision name='collision_top'>
          <pose frame=''>0 0 0.346075 0 -0 0</pose>
          <geometry>
            <box>
              <size>0.127 0.5842 0.01905</size>
            </box>
          </geometry>
          <surface>
            <contact>
              <poissons_ratio>0.347</poissons_ratio>
              <elastic_modulus>8.8e+09</elastic_modulus>
              <ode>
                <kp>100000</kp>
                <kd>100</kd>
                <max_vel>100</max_vel>
                <min_depth>0.001</min_depth>
              </ode>
            </contact>
            <friction>
              <torsional>
                <coefficient>1</coefficient>
                <use_patch_radius>0</use_patch_radius>
                <surface_radius>0.01</surface_radius>
                <ode/>
              </torsional>
              <ode/>
            </friction>
            <bounce/>
          </surface>
          <max_contacts>10</max_contacts>
        </collision>
        <visual name='visual_top'>
          <pose frame=''>0 0 0.346075 0 -0 0</pose>
          <geometry>
            <box>
              <size>0.127 0.5842 0.01905</size>
            </box>
          </geometry>
          <material>
            <script>
              <uri>file://media/materials/scripts/gazebo.material</uri>
              <name>Gazebo/Wood</name>
            </script>
          </material>
        </visual>
        <collision name='collision_left'>
          <pose frame=''>0 -0.282575 0.1778 0 -0 0</pose>
          <geometry>
            <box>
              <size>0.127 0.01905 0.3175</size>
            </box>
          </geometry>
          <surface>
            <contact>
              <poissons_ratio>0.347</poissons_ratio>
              <elastic_modulus>8.8e+09</elastic_modulus>
              <ode>
                <kp>100000</kp>
                <kd>100</kd>
                <max_vel>100</max_vel>
                <min_depth>0.001</min_depth>
              </ode>
            </contact>
            <friction>
              <torsional>
                <coefficient>1</coefficient>
                <use_patch_radius>0</use_patch_radius>
                <surface_radius>0.01</surface_radius>
                <ode/>
              </torsional>
              <ode/>
            </friction>
            <bounce/>
          </surface>
          <max_contacts>10</max_contacts>
        </collision>
        <visual name='visual_left'>
          <pose frame=''>0 -0.282575 0.1778 0 -0 0</pose>
          <geometry>
            <box>
              <size>0.127 0.01905 0.3175</size>
            </box>
          </geometry>
          <material>
            <script>
              <uri>file://media/materials/scripts/gazebo.material</uri>
              <name>Gazebo/Wood</name>
            </script>
          </material>
        </visual>
        <collision name='collision_right'>
          <pose frame=''>0 0.282575 0.1778 0 -0 0</pose>
          <geometry>
            <box>
              <size>0.127 0.01905 0.3175</size>
            </box>
          </geometry>
          <surface>
            <contact>
              <poissons_ratio>0.347</poissons_ratio>
              <elastic_modulus>8.8e+09</elastic_modulus>
              <ode>
                <kp>100000</kp>
                <kd>100</kd>
                <max_vel>100</max_vel>
                <min_depth>0.001</min_depth>
              </ode>
            </contact>
            <friction>
              <torsional>
                <coefficient>1</coefficient>
                <use_patch_radius>0</use_patch_radius>
                <surface_radius>0.01</surface_radius>
                <ode/>
              </torsional>
              <ode/>
            </friction>
            <bounce/>
          </surface>
          <max_contacts>10</max_contacts>
        </collision>
        <visual name='visual_right'>
          <pose frame=''>0 0.282575 0.1778 0 -0 0</pose>
          <geometry>
            <box>
              <size>0.127 0.01905 0.3175</size>
            </box>
          </geometry>
          <material>
            <script>
              <uri>file://media/materials/scripts/gazebo.material</uri>
              <name>Gazebo/Wood</name>
            </script>
          </material>
        </visual>
        <collision name='collision_block_left'>
          <pose frame=''>0.0095 -0.2151 -0.012 0 -0 0</pose>
          <geometry>
            <box>
              <size>0.108 0.05 0.024</size>
            </box>
          </geometry>
          <surface>
            <contact>
              <poissons_ratio>0.347</poissons_ratio>
              <elastic_modulus>8.8e+09</elastic_modulus>
              <ode>
                <kp>100000</kp>
                <kd>100</kd>
                <max_vel>100</max_vel>
                <min_depth>0.001</min_depth>
              </ode>
            </contact>
            <friction>
              <torsional>
                <coefficient>1</coefficient>
                <use_patch_radius>0</use_patch_radius>
                <surface_radius>0.01</surface_radius>
                <ode/>
              </torsional>
              <ode/>
            </friction>
            <bounce/>
          </surface>
          <max_contacts>10</max_contacts>
        </collision>
        <visual name='visual_block_left'>
          <pose frame=''>0.0095 -0.2151 -0.012 0 -0 0</pose>
          <geometry>
            <box>
              <size>0.108 0.05 0.024</size>
            </box>
          </geometry>
          <material>
            <script>
              <uri>file://media/materials/scripts/gazebo.material</uri>
              <name>Gazebo/Wood</name>
            </script>
          </material>
        </visual>
        <collision name='collision_block_right'>
          <pose frame=''>0.0095 0.2151 -0.012 0 -0 0</pose>
          <geometry>
            <box>
              <size>0.108 0.05 0.024</size>
            </box>
          </geometry>
          <surface>
            <contact>
              <poissons_ratio>0.347</poissons_ratio>
              <elastic_modulus>8.8e+09</elastic_modulus>
              <ode>
                <kp>100000</kp>
                <kd>100</kd>
                <max_vel>100</max_vel>
                <min_depth>0.001</min_depth>
              </ode>
            </contact>
            <friction>
              <torsional>
                <coefficient>1</coefficient>
                <use_patch_radius>0</use_patch_radius>
                <surface_radius>0.01</surface_radius>
                <ode/>
              </torsional>
              <ode/>
            </friction>
            <bounce/>
          </surface>
          <max_contacts>10</max_contacts>
        </collision>
        <visual name='visual_block_right'>
          <pose frame=''>0.0095 0.2151 -0.012 0 -0 0</pose>
          <geometry>
            <box>
              <size>0.108 0.05 0.024</size>
            </box>
          </geometry>
          <material>
            <script>
              <uri>file://media/materials/scripts/gazebo.material</uri>
              <name>Gazebo/Wood</name>
            </script>
          </material>
        </visual>
        <self_collide>0</self_collide>
        <kinematic>0</kinematic>
      </link>
      <link name='lid'>
        <pose frame=''>0.243775 0 0.009525 0 -0 0</pose>
        <inertial>
          <mass>1.97874</mass>
          <inertia>
            <ixx>0.0563367</ixx>
            <ixy>0</ixy>
            <ixz>0</ixz>
            <iyy>0.020911</iyy>
            <iyz>0</iyz>
            <izz>0.0771281</izz>
          </inertia>
        </inertial>
        <collision name='collision'>
          <geometry>
            <box>
              <size>0.3556 0.5842 0.01905</size>
            </box>
          </geometry>
          <surface>
            <contact>
              <poissons_ratio>0.347</poissons_ratio>
              <elastic_modulus>8.8e+09</elastic_modulus>
              <ode>
                <kp>100000</kp>
                <kd>100</kd>
                <max_vel>100</max_vel>
                <min_depth>0.001</min_depth>
              </ode>
            </contact>
            <friction>
              <torsional>
                <coefficient>1</coefficient>
                <use_patch_radius>0</use_patch_radius>
                <surface_radius>0.01</surface_radius>
                <ode/>
              </torsional>
              <ode/>
            </friction>
            <bounce/>
          </surface>
          <max_contacts>10</max_contacts>
        </collision>
        <visual name='visual'>
          <geometry>
            <box>
              <size>0.3556 0.5842 0.01905</size>
            </box>
          </geometry>
          <material>
            <script>
              <uri>file://media/materials/scripts/gazebo.material</uri>
              <name>Gazebo/Wood</name>
            </script>
          </material>
        </visual>
        <visual name='tee_nut_1'>
          <pose frame=''>0.122 -0.216 0 0 -0 0</pose>
          <geometry>
            <cylinder>
              <radius>0.00635</radius>
              <length>0.0192405</length>
            </cylinder>
          </geometry>
          <material>
            <script>
              <uri>file://media/materials/scripts/gazebo.material</uri>
              <name>Gazebo/Grey</name>
            </script>
          </material>
        </visual>
        <visual name='tee_nut_2'>
          <pose frame=''>0.122 -0.088 0 0 -0 0</pose>
          <geometry>
            <cylinder>
              <radius>0.00635</radius>
              <length>0.0192405</length>
            </cylinder>
          </geometry>
          <material>
            <script>
              <uri>file://media/materials/scripts/gazebo.material</uri>
              <name>Gazebo/Grey</name>
            </script>
          </material>
        </visual>
        <visual name='tee_nut_3'>
          <pose frame=''>0.122 0.088 0 0 -0 0</pose>
          <geometry>
            <cylinder>
              <radius>0.00635</radius>
              <length>0.0192405</length>
            </cylinder>
          </geometry>
          <material>
            <script>
              <uri>file://media/materials/scripts/gazebo.material</uri>
              <name>Gazebo/Grey</name>
            </script>
          </material>
        </visual>
        <visual name='tee_nut_4'>
          <pose frame=''>0.122 0.216 0 0 -0 0</pose>
          <geometry>
            <cylinder>
              <radius>0.00635</radius>
              <length>0.0192405</length>
            </cylinder>
          </geometry>
          <material>
            <script>
              <uri>file://media/materials/scripts/gazebo.material</uri>
              <name>Gazebo/Grey</name>
            </script>
          </material>
        </visual>
        <self_collide>0</self_collide>
        <kinematic>0</kinematic>
      </link>
      <joint name='lid_hinge' type='revolute'>
        <pose frame=''>-0.1778 0 0.01905 0 -0 0</pose>
        <parent>base</parent>
        <child>lid</child>
        <axis>
          <xyz>0 1 0</xyz>
          <limit>
            <upper>0.523599</upper>
            <lower>-1.5708</lower>
          </limit>
          <use_parent_model_frame>0</use_parent_model_frame>
          <dynamics>
            <spring_reference>0</spring_reference>
            <spring_stiffness>0</spring_stiffness>
          </dynamics>
        </axis>
      </joint>
      <pose frame=''>-1.34958 -0.134456 0 0 -0 0</pose>
    </model>
    <state world_name='default'>
      <sim_time>182 870000000</sim_time>
      <real_time>50 452987513</real_time>
      <wall_time>1576576257 792978779</wall_time>
      <iterations>40985</iterations>
      <model name='drill'>
        <pose frame=''>0.745427 0.094674 -0.002034 0.003017 -0.004461 -0.441929</pose>
        <scale>1 1 1</scale>
        <link name='link'>
          <pose frame=''>0.745427 0.094674 -0.002034 0.003017 -0.004461 -0.441929</pose>
          <velocity>0 0 0 0 -0 0</velocity>
          <acceleration>-0.04042 -0.012028 0.010025 0.079211 -0.286061 -0.121218</acceleration>
          <wrench>-0.060731 -0.018072 0.015062 0 -0 0</wrench>
        </link>
      </model>
      <model name='ground_plane'>
        <pose frame=''>0 0 0 0 -0 0</pose>
        <scale>1 1 1</scale>
        <link name='link'>
          <pose frame=''>0 0 0 0 -0 0</pose>
          <velocity>0 0 0 0 -0 0</velocity>
          <acceleration>0 0 0 0 -0 0</acceleration>
          <wrench>0 0 0 0 -0 0</wrench>
        </link>
      </model>
      <model name='summit_xl'>
        <pose frame=''>-0.001375 3.4e-05 -2.1e-05 5e-06 -1e-06 0</pose>
        <scale>1 1 1</scale>
        <link name='arm_forearm_link'>
          <pose frame=''>-0.171378 -0.016067 0.488556 -3.05746 1.56803 0.084022</pose>
          <velocity>-6e-06 -0.000148 -0.00219 -0.001297 -0.001594 -0.000721</velocity>
          <acceleration>-0.005257 -0.007705 -2.50314 -0.464343 -1.54861 3.02327</acceleration>
          <wrench>-0.011961 -0.017528 -5.69465 0 -0 0</wrench>
        </link>
        <link name='arm_shoulder_link'>
          <pose frame=''>0.253624 3.2e-05 0.489134 -0.000158 0.000614 3.14148</pose>
          <velocity>-0.000206 -0.000499 -0.003356 -0.002213 0.004831 -0.000765</velocity>
          <acceleration>-0.205506 -0.498989 -3.35596 -2.21267 -1.45217 -0.764415</acceleration>
          <wrench>-0.760374 -1.84626 -12.4171 0 -0 0</wrench>
        </link>
        <link name='arm_upper_arm_link'>
          <pose frame=''>0.253608 -0.135818 0.489105 -3.0334 1.56947 0.108075</pose>
          <velocity>-0.000106 -0.00049 -0.002999 -0.002195 0.002676 -0.000781</velocity>
          <acceleration>-0.10718 -0.272584 -2.24962 1.58856 0.462503 3.04911</acceleration>
          <wrench>-0.899565 -2.2878 -18.8811 0 -0 0</wrench>
        </link>
        <link name='arm_wrist_1_link'>
          <pose frame=''>-0.563627 -0.01602 0.487464 -3.14133 -0.003468 -0.000124</pose>
          <velocity>8.5e-05 0.000147 -0.00293 -0.001058 -0.003946 -0.000465</velocity>
          <acceleration>0.041581 0.146853 -2.83215 2.08421 0.804603 2.67759</acceleration>
          <wrench>0.050688 0.179014 -3.45239 0 -0 0</wrench>
        </link>
        <link name='arm_wrist_2_link'>
          <pose frame=''>-0.563639 -0.10902 0.487439 -3.14133 -0.003469 -0.000166</pose>
          <velocity>6.8e-05 0.000137 -0.00284 -0.001003 -0.00394 -0.000615</velocity>
          <acceleration>0.406329 0.059362 -2.89465 -2.70938 1.53619 -0.304679</acceleration>
          <wrench>0.724484 0.105843 -5.16117 0 -0 0</wrench>
        </link>
        <link name='arm_wrist_3_link'>
          <pose frame=''>-0.563311 -0.108994 0.392781 -3.1413 -0.003682 -0.000169</pose>
          <velocity>0.000512 4.1e-05 -0.002955 -0.000647 -0.004525 -0.000455</velocity>
          <acceleration>0.477836 0.04055 -2.90668 2.49503 1.38304 2.68685</acceleration>
          <wrench>0.209245 0.017757 -1.27284 0 -0 0</wrench>
        </link>
        <link name='gripper_left_finger_base_link'>
          <pose frame=''>-0.61034 -0.280436 0.392539 1.57121 -0.004195 -0.000175</pose>
          <velocity>0.000575 5.9e-05 -0.003301 0.000878 -0.01169 -0.000184</velocity>
          <acceleration>0.570233 0.057768 -3.25276 2.63011 -0.926799 3.02067</acceleration>
          <wrench>0.022809 0.002311 -0.13011 0 -0 0</wrench>
        </link>
        <link name='gripper_right_finger_base_link'>
          <pose frame=''>-0.55034 -0.280447 0.392778 -1.5712 0.001813 3.14142</pose>
          <velocity>0.000476 3.7e-05 -0.00285 0.000612 -0.00117 -2.8e-05</velocity>
          <acceleration>0.475289 0.03685 -2.87255 -2.54687 -1.3144 -0.146438</acceleration>
          <wrench>0.019012 0.001474 -0.114902 0 -0 0</wrench>
        </link>
        <link name='summit_xl_back_left_wheel_link'>
          <pose frame=''>-0.223876 0.204534 0.12498 0 -0.010853 0</pose>
          <velocity>-2.5e-05 -9.1e-05 -0.00343 0.000732 -0.000501 3.9e-05</velocity>
          <acceleration>-0.025167 -0.091096 -3.42995 0.732024 -0.501339 0.041232</acceleration>
          <wrench>-0.163583 -0.592124 -22.2947 0 -0 0</wrench>
        </link>
        <link name='summit_xl_back_right_wheel_link'>
          <pose frame=''>-0.223876 -0.204466 0.124978 0 -0.010864 0</pose>
          <velocity>3e-06 -9.1e-05 -0.003998 0.00073 -0.000326 3.4e-05</velocity>
          <acceleration>0.003074 -0.090914 -3.99824 0.730604 -0.325895 0.03639</acceleration>
          <wrench>0.019979 -0.590944 -25.9886 0 -0 0</wrench>
        </link>
        <link name='summit_xl_base_footprint'>
          <pose frame=''>-0.001375 3.4e-05 -2.1e-05 5e-06 -1e-06 0</pose>
          <velocity>7.5e-05 0.000122 -0.003575 0.001312 -0.000592 9.1e-05</velocity>
          <acceleration>-0.004725 -0.053394 -3.56946 1.31201 -0.591941 0.090832</acceleration>
          <wrench>-0.612713 -6.92415 -462.887 0 -0 0</wrench>
        </link>
        <link name='summit_xl_front_left_wheel_link'>
          <pose frame=''>0.221124 0.204534 0.12498 1e-06 -0.010893 -0</pose>
          <velocity>-2.6e-05 -6e-05 -0.003168 0.000486 -0.000484 3.5e-05</velocity>
          <acceleration>-0.02564 -0.060345 -3.16761 0.486563 -0.483568 0.036198</acceleration>
          <wrench>-0.166661 -0.39224 -20.5895 0 -0 0</wrench>
        </link>
        <link name='summit_xl_front_right_wheel_link'>
          <pose frame=''>0.221124 -0.204466 0.124978 0 -0.010895 0</pose>
          <velocity>4e-06 -6.1e-05 -0.003732 0.000489 -0.000298 3.2e-05</velocity>
          <acceleration>0.003822 -0.060625 -3.73238 0.488869 -0.298069 0.033643</acceleration>
          <wrench>0.024846 -0.394064 -24.2605 0 -0 0</wrench>
        </link>
      </model>
      <model name='wooden_case'>
        <pose frame=''>-0.839311 -0.020895 0.06245 -0 -1.57069 -3.12886</pose>
        <scale>1 1 1</scale>
        <link name='base'>
          <pose frame=''>-0.815313 -0.020589 0.062452 -0 -1.57069 -3.12886</pose>
          <velocity>0 0 5.2e-05 0 -3e-06 0</velocity>
          <acceleration>-0.00142 -1.8e-05 -0.002114 0.000841 -0.034364 -0</acceleration>
          <wrench>-0.005625 -7.2e-05 -0.008376 0 -0 0</wrench>
        </link>
        <link name='lid'>
          <pose frame=''>-0.91615 -0.021873 0.272871 0 -1.04709 -3.12886</pose>
          <velocity>0 0 5.2e-05 0 -0 0</velocity>
          <acceleration>-0.009545 -0.000121 -0.011573 0.000675 -0.035296 -3.3e-05</acceleration>
          <wrench>-0.018887 -0.00024 -0.0229 0 -0 0</wrench>
        </link>
      </model>
      <light name='sun'>
        <pose frame=''>0 0 10 0 -0 0</pose>
      </light>
    </state>
    <gui fullscreen='0'>
      <camera name='user_camera'>
        <pose frame=''>2.20484 -3.34219 2.96823 0 0.51964 2.0562</pose>
        <view_controller>orbit</view_controller>
        <projection_type>perspective</projection_type>
      </camera>
    </gui>
  </world>
</sdf>
